<?xml version="1.0" encoding="utf-8"?>
<!-- This URDF was automatically created by SolidWorks to URDF Exporter! Originally created by Stephen Brawner (brawner@gmail.com) 
     Commit Version: 1.6.0-1-g15f4949  Build Version: 1.6.7594.29634
     For more information, please see http://wiki.ros.org/sw_urdf_exporter -->
<robot
  name="4ws_auto_infantry">
  <link
    name="base_link">
    <inertial>
      <origin
        xyz="-0.0153424786189024 -0.000971517176663675 0.0426010747913751"
        rpy="0 0 0" />
      <mass
        value="4.22694944659058" />
      <inertia
        ixx="0.00592574713878002"
        ixy="-6.04761148016892E-07"
        ixz="3.19931122890849E-06"
        iyy="0.00556528018404505"
        iyz="5.11170604999262E-06"
        izz="0.00777661011235666" />
    </inertial>
    <visual>
      <origin
        xyz="0 0 0"
        rpy="0 0 0" />
      <geometry>
        <mesh
          filename="package://4ws_auto_infantry/meshes/base_link.STL" />
      </geometry>
      <material
        name="">
        <color
          rgba="0.792156862745098 0.819607843137255 0.933333333333333 1" />
      </material>
    </visual>
    <collision>
      <origin
        xyz="0 0 0"
        rpy="0 0 0" />
      <geometry>
        <mesh
          filename="package://4ws_auto_infantry/meshes/base_link.STL" />
      </geometry>
    </collision>
  </link>
  <link
    name="fr_steering_link">
    <inertial>
      <origin
        xyz="-8.16524998191182E-05 0.0114879374465855 -0.0535777256855584"
        rpy="0 0 0" />
      <mass
        value="0.233948109921657" />
      <inertia
        ixx="7.48170891927309E-05"
        ixy="7.79475161983056E-08"
        ixz="-2.17674263673885E-07"
        iyy="0.000106662535876269"
        iyz="-5.78832135652101E-08"
        izz="8.18863215714512E-05" />
    </inertial>
    <visual>
      <origin
        xyz="0 0 0"
        rpy="0 0 0" />
      <geometry>
        <mesh
          filename="package://4ws_auto_infantry/meshes/fr_steering_link.STL" />
      </geometry>
      <material
        name="">
        <color
          rgba="0.792156862745098 0.819607843137255 0.933333333333333 1" />
      </material>
    </visual>
    <collision>
      <origin
        xyz="0 0 0"
        rpy="0 0 0" />
      <geometry>
        <mesh
          filename="package://4ws_auto_infantry/meshes/fr_steering_link.STL" />
      </geometry>
    </collision>
  </link>
  <joint
    name="fr_steering_joint"
    type="continuous">
    <origin
      xyz="0.160387678312939 -0.165 0.015664832686077"
      rpy="0 0 0" />
    <parent
      link="base_link" />
    <child
      link="fr_steering_link" />
    <axis
      xyz="0 0 -1" />
  </joint>
  <link
    name="fr_wheel_link">
    <inertial>
      <origin
        xyz="5.82867087928207E-16 0.011380912005585 3.33066907387547E-16"
        rpy="0 0 0" />
      <mass
        value="0.152262957020512" />
      <inertia
        ixx="0.000161899986057917"
        ixy="-4.70045889009574E-19"
        ixz="-1.20026720731511E-07"
        iyy="0.000308108500845025"
        iyz="7.35542109619805E-19"
        izz="0.000162472065076815" />
    </inertial>
    <visual>
      <origin
        xyz="0 0 0"
        rpy="0 0 0" />
      <geometry>
        <mesh
          filename="package://4ws_auto_infantry/meshes/fr_wheel_link.STL" />
      </geometry>
      <material
        name="">
        <color
          rgba="0.792156862745098 0.819607843137255 0.933333333333333 1" />
      </material>
    </visual>
    <collision>
      <origin
        xyz="0 0 0"
        rpy="0 0 0" />
      <geometry>
        <mesh
          filename="package://4ws_auto_infantry/meshes/fr_wheel_link.STL" />
      </geometry>
    </collision>
  </link>
  <joint
    name="fr_wheel_joint"
    type="continuous">
    <origin
      xyz="-5.00000000002165E-05 -0.0119999999999999 -0.07"
      rpy="0 0 0" />
    <parent
      link="fr_steering_link" />
    <child
      link="fr_wheel_link" />
    <axis
      xyz="0 1 0" />
  </joint>
  <link
    name="fl_steering_link">
    <inertial>
      <origin
        xyz="-8.16524991866796E-05 0.011487937432077 -0.0535777256826572"
        rpy="0 0 0" />
      <mass
        value="0.233948109854195" />
      <inertia
        ixx="7.48170891762637E-05"
        ixy="7.79475140131296E-08"
        ixz="-2.17674267008069E-07"
        iyy="0.000106662535864513"
        iyz="-5.78832080302591E-08"
        izz="8.18863215576112E-05" />
    </inertial>
    <visual>
      <origin
        xyz="0 0 0"
        rpy="0 0 0" />
      <geometry>
        <mesh
          filename="package://4ws_auto_infantry/meshes/fl_steering_link.STL" />
      </geometry>
      <material
        name="">
        <color
          rgba="0.792156862745098 0.819607843137255 0.933333333333333 1" />
      </material>
    </visual>
    <collision>
      <origin
        xyz="0 0 0"
        rpy="0 0 0" />
      <geometry>
        <mesh
          filename="package://4ws_auto_infantry/meshes/fl_steering_link.STL" />
      </geometry>
    </collision>
  </link>
  <joint
    name="fl_steering_joint"
    type="continuous">
    <origin
      xyz="0.160387678312938 0.165000000000001 0.0156648397333951"
      rpy="0 0 0" />
    <parent
      link="base_link" />
    <child
      link="fl_steering_link" />
    <axis
      xyz="0 0 -1" />
  </joint>
  <link
    name="fl_wheel_link">
    <inertial>
      <origin
        xyz="8.32667268468867E-17 0.0113809120055849 -6.66133814775094E-16"
        rpy="0 0 0" />
      <mass
        value="0.152262957020512" />
      <inertia
        ixx="0.00016249459058406"
        ixy="-2.53064094491269E-19"
        ixz="3.18220855376168E-08"
        iyy="0.000308108500845026"
        iyz="7.0728165439244E-19"
        izz="0.000161877460550672" />
    </inertial>
    <visual>
      <origin
        xyz="0 0 0"
        rpy="0 0 0" />
      <geometry>
        <mesh
          filename="package://4ws_auto_infantry/meshes/fl_wheel_link.STL" />
      </geometry>
      <material
        name="">
        <color
          rgba="0.792156862745098 0.819607843137255 0.933333333333333 1" />
      </material>
    </visual>
    <collision>
      <origin
        xyz="0 0 0"
        rpy="0 0 0" />
      <geometry>
        <mesh
          filename="package://4ws_auto_infantry/meshes/fl_wheel_link.STL" />
      </geometry>
    </collision>
  </link>
  <joint
    name="fl_wheel_joint"
    type="continuous">
    <origin
      xyz="-4.99999999996614E-05 -0.0119999999999999 -0.0699999999999988"
      rpy="0 0 0" />
    <parent
      link="fl_steering_link" />
    <child
      link="fl_wheel_link" />
    <axis
      xyz="0 1 0" />
  </joint>
  <link
    name="bl_steering_link">
    <inertial>
      <origin
        xyz="-8.16524987842515E-05 0.0114879374365965 -0.0535777256831927"
        rpy="0 0 0" />
      <mass
        value="0.233948109874449" />
      <inertia
        ixx="7.48170891818403E-05"
        ixy="7.7947513379771E-08"
        ixz="-2.17674266878774E-07"
        iyy="0.000106662535868677"
        iyz="-5.78832110503779E-08"
        izz="8.18863215620746E-05" />
    </inertial>
    <visual>
      <origin
        xyz="0 0 0"
        rpy="0 0 0" />
      <geometry>
        <mesh
          filename="package://4ws_auto_infantry/meshes/bl_steering_link.STL" />
      </geometry>
      <material
        name="">
        <color
          rgba="0.792156862745098 0.819607843137255 0.933333333333333 1" />
      </material>
    </visual>
    <collision>
      <origin
        xyz="0 0 0"
        rpy="0 0 0" />
      <geometry>
        <mesh
          filename="package://4ws_auto_infantry/meshes/bl_steering_link.STL" />
      </geometry>
    </collision>
  </link>
  <joint
    name="bl_steering_joint"
    type="continuous">
    <origin
      xyz="-0.169612321687062 0.164999999999999 0.0156648361657047"
      rpy="0 0 0" />
    <parent
      link="base_link" />
    <child
      link="bl_steering_link" />
    <axis
      xyz="0 0 -1" />
  </joint>
  <link
    name="bl_wheel_link">
    <inertial>
      <origin
        xyz="2.77555756156289E-16 0.011380912005585 6.10622663543836E-16"
        rpy="0 0 0" />
      <mass
        value="0.152262957020512" />
      <inertia
        ixx="0.000162339119130636"
        ixy="-5.83271855638504E-19"
        ixz="-2.69791355571105E-07"
        iyy="0.000308108500845026"
        iyz="6.61486285374226E-19"
        izz="0.000162032932004097" />
    </inertial>
    <visual>
      <origin
        xyz="0 0 0"
        rpy="0 0 0" />
      <geometry>
        <mesh
          filename="package://4ws_auto_infantry/meshes/bl_wheel_link.STL" />
      </geometry>
      <material
        name="">
        <color
          rgba="0.792156862745098 0.819607843137255 0.933333333333333 1" />
      </material>
    </visual>
    <collision>
      <origin
        xyz="0 0 0"
        rpy="0 0 0" />
      <geometry>
        <mesh
          filename="package://4ws_auto_infantry/meshes/bl_wheel_link.STL" />
      </geometry>
    </collision>
  </link>
  <joint
    name="bl_wheel_joint"
    type="continuous">
    <origin
      xyz="-4.9999999999828E-05 -0.0119999999999999 -0.0700000000000005"
      rpy="0 0 0" />
    <parent
      link="bl_steering_link" />
    <child
      link="bl_wheel_link" />
    <axis
      xyz="0 1 0" />
  </joint>
  <link
    name="br_steering_link">
    <inertial>
      <origin
        xyz="-8.16524988057898E-05 0.0114879374333171 -0.0535777256832153"
        rpy="0 0 0" />
      <mass
        value="0.233948109858844" />
      <inertia
        ixx="7.48170891767385E-05"
        ixy="7.7947513452403E-08"
        ixz="-2.17674267182683E-07"
        iyy="0.000106662535865159"
        iyz="-5.78832079378798E-08"
        izz="8.18863215601841E-05" />
    </inertial>
    <visual>
      <origin
        xyz="0 0 0"
        rpy="0 0 0" />
      <geometry>
        <mesh
          filename="package://4ws_auto_infantry/meshes/br_steering_link.STL" />
      </geometry>
      <material
        name="">
        <color
          rgba="0.792156862745098 0.819607843137255 0.933333333333333 1" />
      </material>
    </visual>
    <collision>
      <origin
        xyz="0 0 0"
        rpy="0 0 0" />
      <geometry>
        <mesh
          filename="package://4ws_auto_infantry/meshes/br_steering_link.STL" />
      </geometry>
    </collision>
  </link>
  <joint
    name="br_steering_joint"
    type="continuous">
    <origin
      xyz="-0.169612321687061 -0.165000000000001 0.0154600000000106"
      rpy="0 0 0" />
    <parent
      link="base_link" />
    <child
      link="br_steering_link" />
    <axis
      xyz="0 0 -1" />
  </joint>
  <link
    name="br_wheel_link">
    <inertial>
      <origin
        xyz="6.38378239159465E-16 0.011380912005585 -2.77555756156289E-16"
        rpy="0 0 0" />
      <mass
        value="0.152262957020512" />
      <inertia
        ixx="0.000162016542300868"
        ixy="-3.60390069951356E-19"
        ixz="2.59808462203538E-07"
        iyy="0.000308108500845026"
        iyz="8.24222567278785E-19"
        izz="0.000162355508833864" />
    </inertial>
    <visual>
      <origin
        xyz="0 0 0"
        rpy="0 0 0" />
      <geometry>
        <mesh
          filename="package://4ws_auto_infantry/meshes/br_wheel_link.STL" />
      </geometry>
      <material
        name="">
        <color
          rgba="0.792156862745098 0.819607843137255 0.933333333333333 1" />
      </material>
    </visual>
    <collision>
      <origin
        xyz="0 0 0"
        rpy="0 0 0" />
      <geometry>
        <mesh
          filename="package://4ws_auto_infantry/meshes/br_wheel_link.STL" />
      </geometry>
    </collision>
  </link>
  <joint
    name="br_wheel_joint"
    type="continuous">
    <origin
      xyz="-5.00000000003831E-05 -0.012 -0.0699999999999993"
      rpy="0 0 0" />
    <parent
      link="br_steering_link" />
    <child
      link="br_wheel_link" />
    <axis
      xyz="0 1 0" />
  </joint>
  <link
    name="yaw_link">
    <inertial>
      <origin
        xyz="0.0033026586971186 -0.00141433442026462 0.0492017467960623"
        rpy="0 0 0" />
      <mass
        value="0.200860330559733" />
      <inertia
        ixx="0.000989192198602812"
        ixy="-1.3529226863658E-06"
        ixz="-2.85373821110227E-05"
        iyy="0.000659302734650477"
        iyz="2.94840176363339E-05"
        izz="0.000888939800483085" />
    </inertial>
    <visual>
      <origin
        xyz="0 0 0"
        rpy="0 0 0" />
      <geometry>
        <mesh
          filename="package://4ws_auto_infantry/meshes/yaw_link.STL" />
      </geometry>
      <material
        name="">
        <color
          rgba="1 1 1 1" />
      </material>
    </visual>
    <collision>
      <origin
        xyz="0 0 0"
        rpy="0 0 0" />
      <geometry>
        <mesh
          filename="package://4ws_auto_infantry/meshes/yaw_link.STL" />
      </geometry>
    </collision>
  </link>
  <joint
    name="yaw_joint"
    type="continuous">
    <origin
      xyz="-0.00461231611052366 0 0.08799999999999"
      rpy="0 0 0" />
    <parent
      link="base_link" />
    <child
      link="yaw_link" />
    <axis
      xyz="0 0 -1" />
  </joint>
  <link
    name="pitch_link">
    <inertial>
      <origin
        xyz="0.0218295214644216 -0.00572718193836697 0.0223154294531415"
        rpy="0 0 0" />
      <mass
        value="1.36996603358887" />
      <inertia
        ixx="0.000869741345762696"
        ixy="1.93480998509698E-06"
        ixz="1.49079616459806E-05"
        iyy="0.00321720011981406"
        iyz="-1.2188670424588E-06"
        izz="0.0036436239270771" />
    </inertial>
    <visual>
      <origin
        xyz="0 0 0"
        rpy="0 0 0" />
      <geometry>
        <mesh
          filename="package://4ws_auto_infantry/meshes/pitch_link.STL" />
      </geometry>
      <material
        name="">
        <color
          rgba="1 1 1 1" />
      </material>
    </visual>
    <collision>
      <origin
        xyz="0 0 0"
        rpy="0 0 0" />
      <geometry>
        <mesh
          filename="package://4ws_auto_infantry/meshes/pitch_link.STL" />
      </geometry>
    </collision>
  </link>
  <joint
    name="pitch_joint"
    type="continuous">
    <origin
      xyz="0 0 0.152999458706042"
      rpy="0 0 0" />
    <parent
      link="yaw_link" />
    <child
      link="pitch_link" />
    <axis
      xyz="0 -1 0" />
  </joint>
  <link
    name="cam_link">
    <inertial>
      <origin
        xyz="-0.0333625192776818 7.78704694743004E-05 1.8912045142816E-05"
        rpy="0 0 0" />
      <mass
        value="0.135798863176648" />
      <inertia
        ixx="1.71413025492174E-05"
        ixy="4.60151773237999E-07"
        ixz="4.95362807343211E-08"
        iyy="5.9443792104674E-05"
        iyz="8.80056228730057E-08"
        izz="5.95685810229894E-05" />
    </inertial>
    <visual>
      <origin
        xyz="0 0 0"
        rpy="0 0 0" />
      <geometry>
        <mesh
          filename="package://4ws_auto_infantry/meshes/cam_link.STL" />
      </geometry>
      <material
        name="">
        <color
          rgba="0.792156862745098 0.819607843137255 0.933333333333333 1" />
      </material>
    </visual>
    <collision>
      <origin
        xyz="0 0 0"
        rpy="0 0 0" />
      <geometry>
        <mesh
          filename="package://4ws_auto_infantry/meshes/cam_link.STL" />
      </geometry>
    </collision>
  </link>
  <joint
    name="cam_joint"
    type="fixed">
    <origin
      xyz="0.13112 -0.00050216534503969 0.0420000000000005"
      rpy="0 0 0" />
    <parent
      link="pitch_link" />
    <child
      link="cam_link" />
    <axis
      xyz="0 0 0" />
  </joint>
  <link
    name="lidar_1_link">
    <inertial>
      <origin
        xyz="0.00800003791293047 0.0139524588145136 -0.056592110155703"
        rpy="0 0 0" />
      <mass
        value="0.0554197871614723" />
      <inertia
        ixx="2.42532146536024E-05"
        ixy="-4.08523458007044E-07"
        ixz="5.99955362116005E-08"
        iyy="2.44427501355239E-05"
        iyz="9.89324286287192E-09"
        izz="3.51059136781273E-05" />
    </inertial>
    <visual>
      <origin
        xyz="0 0 0"
        rpy="0 0 0" />
      <geometry>
        <mesh
          filename="package://4ws_auto_infantry/meshes/lidar_1_link.STL" />
      </geometry>
      <material
        name="">
        <color
          rgba="0.294117647058824 0.294117647058824 0.294117647058824 1" />
      </material>
    </visual>
    <collision>
      <origin
        xyz="0 0 0"
        rpy="0 0 0" />
      <geometry>
        <mesh
          filename="package://4ws_auto_infantry/meshes/lidar_1_link.STL" />
      </geometry>
    </collision>
  </link>
  <joint
    name="lidar_1_joint"
    type="fixed">
    <origin
      xyz="0.143385236440617 -0.14607365029173 0.170364832686067"
      rpy="0 0 0" />
    <parent
      link="base_link" />
    <child
      link="lidar_1_link" />
    <axis
      xyz="0 0 0" />
  </joint>
  <link
    name="lidar_2_link">
    <inertial>
      <origin
        xyz="-0.00799578661074335 -0.0139548956508409 -0.0565921103741513"
        rpy="0 0 0" />
      <mass
        value="0.0554197869273259" />
      <inertia
        ixx="2.42534635190261E-05"
        ixy="-4.08581151251797E-07"
        ixz="-5.9992463019726E-08"
        iyy="2.44425010541392E-05"
        iyz="-9.91155171917584E-09"
        izz="3.51059136436725E-05" />
    </inertial>
    <visual>
      <origin
        xyz="0 0 0"
        rpy="0 0 0" />
      <geometry>
        <mesh
          filename="package://4ws_auto_infantry/meshes/lidar_2_link.STL" />
      </geometry>
      <material
        name="">
        <color
          rgba="0.294117647058824 0.294117647058824 0.294117647058824 1" />
      </material>
    </visual>
    <collision>
      <origin
        xyz="0 0 0"
        rpy="0 0 0" />
      <geometry>
        <mesh
          filename="package://4ws_auto_infantry/meshes/lidar_2_link.STL" />
      </geometry>
    </collision>
  </link>
  <joint
    name="lidar_2_joint"
    type="prismatic">
    <origin
      xyz="-0.154275039887516 0.151073668429019 0.170364832686068"
      rpy="0 0 0" />
    <parent
      link="base_link" />
    <child
      link="lidar_2_link" />
    <axis
      xyz="0.707214493379366 -0.706999052583642 0" />
    <limit
      lower="0"
      upper="0"
      effort="0"
      velocity="0" />
  </joint>
  <link
    name="imu_link">
    <inertial>
      <origin
        xyz="-0.000490931902507874 8.33499974040031E-08 -0.0128774712286312"
        rpy="0 0 0" />
      <mass
        value="0.0152032914019641" />
      <inertia
        ixx="3.58585897336552E-06"
        ixy="1.07037003961398E-13"
        ixz="-1.60040769048652E-09"
        iyy="3.45316263291563E-06"
        iyz="5.26240295635906E-13"
        izz="5.64618660363721E-06" />
    </inertial>
    <visual>
      <origin
        xyz="0 0 0"
        rpy="0 0 0" />
      <geometry>
        <mesh
          filename="package://4ws_auto_infantry/meshes/imu_link.STL" />
      </geometry>
      <material
        name="">
        <color
          rgba="1 1 1 1" />
      </material>
    </visual>
    <collision>
      <origin
        xyz="0 0 0"
        rpy="0 0 0" />
      <geometry>
        <mesh
          filename="package://4ws_auto_infantry/meshes/imu_link.STL" />
      </geometry>
    </collision>
  </link>
  <joint
    name="imu_joint"
    type="fixed">
    <origin
      xyz="0.130808431401769 -0.000220675328304477 0.0279999999999999"
      rpy="0 0 0" />
    <parent
      link="base_link" />
    <child
      link="imu_link" />
    <axis
      xyz="0 0 0" />
  </joint>
</robot>
